<?xml version="1.0" encoding="utf-8"?>
<!-- This URDF was automatically created by SolidWorks to URDF Exporter! Originally created by Stephen Brawner (brawner@gmail.com) 
     Commit Version: 1.6.0-1-g15f4949  Build Version: 1.6.7594.29634
     For more information, please see http://wiki.ros.org/sw_urdf_exporter -->
<robot
  name="robot_description">

<link name="base_footprint"/>
  <joint name="joint_base"
    type="fixed">
    <origin
      xyz="0 0 0.035"
      rpy="0 0 0" />
    <parent
      link="base_footprint" />
    <child
      link="base_link" />
  </joint>

  <link
    name="base_link">
    <inertial>
      <origin
        xyz="0.011251388694839 -0.000218371431547896 0.0399880408960165"
        rpy="0 0 0" />
      <mass
        value="3.10332964553309" />
      <inertia
        ixx="0.0281276630484449"
        ixy="3.5116427776902E-08"
        ixz="-0.00469879010404139"
        iyy="0.0668672613470827"
        iyz="-3.61597758280749E-07"
        izz="0.0746126560387773" />
    </inertial>
    <visual>
      <origin
        xyz="0 0 0"
        rpy="0 0 0" />
      <geometry>
        <mesh
          filename="package://robot_description/meshes/base_link.STL" />
      </geometry>
      <material
        name="">
        <color
          rgba="0.792156862745098 0.819607843137255 0.933333333333333 1" />
      </material>
    </visual>
    <collision>
      <origin
        xyz="0 0 0"
        rpy="0 0 0" />
      <geometry>
        <mesh
          filename="package://robot_description/meshes/base_link.STL" />
      </geometry>
    </collision>
  </link>
  <link
    name="left_wheel_link">
    <inertial>
      <origin
        xyz="-6.43950559542361E-10 0.000697154054652038 -3.84037496248268E-10"
        rpy="0 0 0" />
      <mass
        value="0.0525886389300759" />
      <inertia
        ixx="2.2276561780029E-05"
        ixy="-2.14170927054796E-13"
        ixz="-1.36754384280771E-13"
        iyy="3.95813257450557E-05"
        iyz="-4.75100954008714E-14"
        izz="2.22767408662809E-05" />
    </inertial>
    <visual>
      <origin
        xyz="0 0 0"
        rpy="0 0 0" />
      <geometry>
        <mesh
          filename="package://robot_description/meshes/left_wheel_link.STL" />
      </geometry>
      <material
        name="">
        <color
          rgba="0.792156862745098 0.819607843137255 0.933333333333333 1" />
      </material>
    </visual>
    <collision>
      <origin
        xyz="0 0 0"
        rpy="0 0 0" />
      <geometry>
        <mesh
          filename="package://robot_description/meshes/left_wheel_link.STL" />
      </geometry>
    </collision>
  </link>
  <joint
    name="left_wheel_joint"
    type="continuous">
    <origin
      xyz="0.1385 0.121 -0.054"
      rpy="0 0 0" />
    <parent
      link="base_link" />
    <child
      link="left_wheel_link" />
    <axis
      xyz="0 1 0" />
  </joint>
  <link
    name="right_wheel_link">
    <inertial>
      <origin
        xyz="6.43950559542361E-10 -0.000697154054652052 -3.84037440737117E-10"
        rpy="0 0 0" />
      <mass
        value="0.052588638930076" />
      <inertia
        ixx="2.22765617800291E-05"
        ixy="-2.14170904417189E-13"
        ixz="1.36754355686708E-13"
        iyy="3.95813257450558E-05"
        iyz="4.75101076736735E-14"
        izz="2.22767408662809E-05" />
    </inertial>
    <visual>
      <origin
        xyz="0 0 0"
        rpy="0 0 0" />
      <geometry>
        <mesh
          filename="package://robot_description/meshes/right_wheel_link.STL" />
      </geometry>
      <material
        name="">
        <color
          rgba="0.792156862745098 0.819607843137255 0.933333333333333 1" />
      </material>
    </visual>
    <collision>
      <origin
        xyz="0 0 0"
        rpy="0 0 0" />
      <geometry>
        <mesh
          filename="package://robot_description/meshes/right_wheel_link.STL" />
      </geometry>
    </collision>
  </link>
  <joint
    name="right_wheel_joint"
    type="continuous">
    <origin
      xyz="0.1385 -0.121 -0.054"
      rpy="0 0 0" />
    <parent
      link="base_link" />
    <child
      link="right_wheel_link" />
    <axis
      xyz="0 1 0" />
  </joint>
  <link
    name="left_caster_link">
    <inertial>
      <origin
        xyz="0.00842140438424113 -0.000116137901313776 -0.0269930296093085"
        rpy="0 0 0" />
      <mass
        value="0.0848685945513389" />
      <inertia
        ixx="2.32697424754144E-05"
        ixy="-1.44036304353653E-09"
        ixz="9.6149940655632E-07"
        iyy="2.44981679825654E-05"
        iyz="1.79135201929634E-09"
        izz="2.58335825567553E-05" />
    </inertial>
    <visual>
      <origin
        xyz="0 0 0"
        rpy="0 0 0" />
      <geometry>
        <mesh
          filename="package://robot_description/meshes/left_caster_link.STL" />
      </geometry>
      <material
        name="">
        <color
          rgba="0.698039215686274 0.698039215686274 0.698039215686274 1" />
      </material>
    </visual>
    <collision>
      <origin
        xyz="0 0 0"
        rpy="0 0 0" />
      <geometry>
        <mesh
          filename="package://robot_description/meshes/left_caster_link.STL" />
      </geometry>
    </collision>
  </link>
  <joint
    name="left_caster_joint"
    type="fixed">
    <origin
      xyz="-0.1535 0.09 -0.025"
      rpy="0 0 0" />
    <parent
      link="base_link" />
    <child
      link="left_caster_link" />
    <axis
      xyz="0 0 0" />
  </joint>
  <link
    name="right_caster_link">
    <inertial>
      <origin
        xyz="0.00842140438424113 -0.000116137901313693 -0.0269930296093086"
        rpy="0 0 0" />
      <mass
        value="0.0848685945513389" />
      <inertia
        ixx="2.32697424754136E-05"
        ixy="-1.44036304353131E-09"
        ixz="9.61499406556324E-07"
        iyy="2.44981679825639E-05"
        iyz="1.79135201927591E-09"
        izz="2.58335825567545E-05" />
    </inertial>
    <visual>
      <origin
        xyz="0 0 0"
        rpy="0 0 0" />
      <geometry>
        <mesh
          filename="package://robot_description/meshes/right_caster_link.STL" />
      </geometry>
      <material
        name="">
        <color
          rgba="0.698039215686274 0.698039215686274 0.698039215686274 1" />
      </material>
    </visual>
    <collision>
      <origin
        xyz="0 0 0"
        rpy="0 0 0" />
      <geometry>
        <mesh
          filename="package://robot_description/meshes/right_caster_link.STL" />
      </geometry>
    </collision>
  </link>
  <joint
    name="right_caster_joint"
    type="fixed">
    <origin
      xyz="-0.1535 -0.09 -0.025"
      rpy="0 0 0" />
    <parent
      link="base_link" />
    <child
      link="right_caster_link" />
    <axis
      xyz="0 0 0" />
  </joint>
  <link
    name="lidar_link">
    <inertial>
      <origin
        xyz="-0.00676653011666356 -0.00838187226715975 -9.19261110875395E-05"
        rpy="0 0 0" />
      <mass
        value="0.33076913637071" />
      <inertia
        ixx="0.000614917940454091"
        ixy="-0.00015824302591117"
        ixz="8.01984318975235E-07"
        iyy="0.00109815200027136"
        iyz="-3.09162986587573E-06"
        izz="0.000960697335617223" />
    </inertial>
    <visual>
      <origin
        xyz="0 0 0"
        rpy="0 0 0" />
      <geometry>
        <mesh
          filename="package://robot_description/meshes/lidar_link.STL" />
      </geometry>
      <material
        name="">
        <color
          rgba="0.792156862745098 0.819607843137255 0.933333333333333 1" />
      </material>
    </visual>
    <collision>
      <origin
        xyz="0 0 0"
        rpy="0 0 0" />
      <geometry>
        <mesh
          filename="package://robot_description/meshes/lidar_link.STL" />
      </geometry>
    </collision>
  </link>
  <joint
    name="lidar_joint"
    type="fixed">
    <origin
      xyz="0.22425 0 0.40365"
      rpy="0.0 0 0" />
    <parent
      link="base_link" />
    <child
      link="lidar_link" />
    <axis
      xyz="0 0 0" />
  </joint>


 <gazebo reference="left_wheel_link">
    <mu1>1.0</mu1>
    <mu2>1.0</mu2>
    <kp>500000.0</kp>
    <kd>100.0</kd>
    <minDepth>0.001</minDepth>
    <maxVel>2</maxVel>
    <fdir1>0 0 1</fdir1>
    <material>Gazebo/FlatBlack</material>
  </gazebo>

 <gazebo reference="right_wheel_link">
    <mu1>1.0</mu1>
    <mu2>1.0</mu2>
    <kp>500000.0</kp>
    <kd>100.0</kd>
    <minDepth>0.001</minDepth>
    <maxVel>2</maxVel>
    <fdir1>0 0 1</fdir1>
    <material>Gazebo/FlatBlack</material>
  </gazebo>


 <gazebo reference="left_caster_link">
    <mu1>0.1</mu1>
    <mu2>0.1</mu2>
    <kp>500.0</kp>
    <kd>10.0</kd>
    <minDepth>0.001</minDepth>
    <maxVel>2</maxVel>
    <fdir1>0 0 1</fdir1>
    <material>Gazebo/FlatBlack</material>
  </gazebo>

 <gazebo reference="right_caster_link">
    <mu1>0.1</mu1>
    <mu2>0.1</mu2>
    <kp>500.0</kp>
    <kd>10.0</kd>
    <minDepth>0.001</minDepth>
    <maxVel>2</maxVel>
    <fdir1>0 0 1</fdir1>
    <material>Gazebo/FlatBlack</material>
  </gazebo>

<gazebo>
	  <plugin name="differential_drive_controller"
		filename="libgazebo_ros_diff_drive.so">
    <leftJoint>left_wheel_joint</leftJoint>
	  <rightJoint>right_wheel_joint</rightJoint>
  	<robotBaseFrame>base_footprint</robotBaseFrame>
  	<wheelSeparation>0.15</wheelSeparation>
  	<wheelDiameter>0.07</wheelDiameter>
	  <commandTopic>cmd_vel</commandTopic>
    <odometryTopic>odom</odometryTopic>
  	<odometryFrame>odom</odometryFrame>
    <odometrySource>world</odometrySource>
    <publishOdomTF>true</publishOdomTF>
  	<publishWheelTF>false</publishWheelTF>

      <publishTf>true</publishTf>
      	<publishWheelJointState>true</publishWheelJointState>
      	<legacyMode>false</legacyMode>
      	<updateRate>100.0</updateRate>
	<wheelAcceleration>6</wheelAcceleration>
      	<wheelTorque>20</wheelTorque>
     	<rosDebugLevel>na</rosDebugLevel>
	    </plugin>
</gazebo>
<!-- -->

 <gazebo reference="lidar_link">
    <material>Gazebo/FlatBlack</material>
    <sensor type="gpu_ray" name="lidar_link_sensor">
      <pose>0 0 0 0 0 0</pose>
      <visualize>false</visualize>
      <update_rate>5</update_rate>
      <ray>
        <scan>
          <horizontal>
            <samples>720</samples>
            <resolution>1</resolution>
            <min_angle>0.0</min_angle>
            <max_angle>6.28319</max_angle>
          </horizontal>
        </scan>
        <range>
          <min>0.50</min>
          <max>8.5</max>
          <resolution>0.015</resolution>
        </range>
        <noise>
          <type>gaussian</type>
          <mean>0.0</mean>
          <stddev>0.01</stddev>
        </noise>
      </ray>
      <plugin name="gazebo_ros_lds_lfcd_controller" filename="libgazebo_ros_gpu_laser.so">
        <topicName>/scan</topicName>
        <frameName>lidar_link</frameName>
      </plugin>
    </sensor>
  </gazebo>

</robot>
